Workbook
Name Slicer_Artist: #N/A

Sheet 2.09.2021
A1: Numele Melodiei | B1: Artist | C1: Numar vizualizari | D1: Venituri | E1: Data Lansarii | F1: Aparitii in top 200 | G1: Durata Melodiei | H1: Genul de Muzica | I1: Naționalitatea artistului | J1: Colaborare
A3: STAY (with Justin Bieber) | B3: The Kid LAROI | C3: 68764542 | D3: =(C3/1000*5) -> 343822.71 | E3: 44386 | F3: 44441 | G3: 0.097916667 | H3: POP | I3: Australia | J3: =IF(ISNUMBER(SEARCH("with",A3)),"Da","Nu") -> Da
A4: INDUSTRY BABY (with Jack Harlow) | B4: Lil Nas X | C4: 43663527 | D4: =(C4/1000*5) -> 218317.64 | E4: 44400 | F4: 44441 | G4: 0.14722222 | H4: HIP-HOP/RAP | I4: SUA | J4: =IF(ISNUMBER(SEARCH("with",A4)),"Da","Nu") -> Da
A5: Bad Habits | B5: Ed Sheeran | C5: 34182580 | D5: =(C5/1000*5) -> 170912.9 | E5: 44358 | F5: 44441 | G5: 0.14722222 | H5: POP | I5: Marea Britanie | J5: =IF(ISNUMBER(SEARCH("with",A5)),"Da","Nu") -> Nu
A6: Beggin' | B6: Måneskin | C6: 32620597 | D6: =(C6/1000*5) -> 163102.99 | E6: 43077 | F6: 44441 | G6: 0.14652778 | H6: ROCK | I6: Italia | J6: =IF(ISNUMBER(SEARCH("with",A6)),"Da","Nu") -> Nu
A7: Hurricane | B7: Kanye West | C7: 30609671 | D7: =(C7/1000*5) -> 153048.35 | E7: 44416 | F7: 44441 | G7: 0.16875 | H7: HIP-HOP/RAP | I7: SUA | J7: =IF(ISNUMBER(SEARCH("with",A7)),"Da","Nu") -> Nu
A8: Pepas | B8: Farruko | C8: 29398007 | D8: =(C8/1000*5) -> 146990.04 | E8: 44538 | F8: 44441 | G8: 0.19930556 | H8: LATIN URBAN | I8: Puerto Rico | J8: =IF(ISNUMBER(SEARCH("with",A8)),"Da","Nu") -> Nu
A9: good 4 u | B9: Olivia Rodrigo | C9: 29366737 | D9: =(C9/1000*5) -> 146833.68 | E9: 44337 | F9: 44441 | G9: 0.12361111 | H9: POP | I9: SUA | J9: =IF(ISNUMBER(SEARCH("with",A9)),"Da","Nu") -> Nu
A10: Need To Know | B10: Doja Cat | C10: 28000403 | D10: =(C10/1000*5) -> 140002.01 | E10: 44371 | F10: 44441 | G10: 0.14583333 | H10: POP | I10: SUA | J10: =IF(ISNUMBER(SEARCH("with",A10)),"Da","Nu") -> Nu
A11: Woman | B11: Doja Cat | C11: 26632882 | D11: =(C11/1000*5) -> 133164.41 | E11: 44374 | F11: 44441 | G11: 0.10069444 | H11: POP | I11: SUA | J11: =IF(ISNUMBER(SEARCH("with",A11)),"Da","Nu") -> Nu
A12: Jail | B12: Kanye West | C12: 24792859 | D12: =(C12/1000*5) -> 123964.29 | E12: 44437 | F12: 44441 | G12: 0.20625 | H12: HIP-HOP/RAP | I12: SUA | J12: =IF(ISNUMBER(SEARCH("with",A12)),"Da","Nu") -> Nu
A13: Happier Than Ever | B13: Billie Eilish | C13: 24448545 | D13: =(C13/1000*5) -> 122242.72 | E13: 44407 | F13: 44441 | G13: 0.20694444 | H13: ALTERNATIVE | I13: SUA | J13: =IF(ISNUMBER(SEARCH("with",A13)),"Da","Nu") -> Nu
A14: Off The Grid | B14: Kanye West | C14: 24302344 | D14: =(C14/1000*5) -> 121511.72 | E14: 44437 | F14: 44441 | G14: 0.23541667 | H14: HIP-HOP/RAP | I14: SUA | J14: =IF(ISNUMBER(SEARCH("with",A14)),"Da","Nu") -> Nu
... A44: AM Remix | B44: Nio Garcia | C44: 13082669 | D44: =(C44/1000*5) -> 65413.345 | E44: 44371 | F44: 44441 | G44: 0.18125 | H44: LATIN URBAN | I44: Puerto Rico | J44: =IF(ISNUMBER(SEARCH("with",A44)),"Da","Nu") -> Nu
A45: 24 | B45: Kanye West | C45: 12955187 | D45: =(C45/1000*5) -> 64775.935 | E45: 44437 | F45: 44441 | G45: 0.13680556 | H45: HIP-HOP/RAP | I45: SUA | J45: =IF(ISNUMBER(SEARCH("with",A45)),"Da","Nu") -> Nu
A46: In Da Getto | B46: J Balvin | C46: 12933235 | D46: =(C46/1000*5) -> 64666.175 | E46: 44379 | F46: 44441 | G46: 0.090277778 | H46: LATIN URBAN | I46: Columbia | J46: =IF(ISNUMBER(SEARCH("with",A46)),"Da","Nu") -> Nu
A47: Remote Control | B47: Kanye West | C47: 12913533 | D47: =(C47/1000*5) -> 64567.665 | E47: 44437 | F47: 44441 | G47: 0.1375 | H47: HIP-HOP/RAP | I47: SUA | J47: =IF(ISNUMBER(SEARCH("with",A47)),"Da","Nu") -> Nu
A48: drivers license | B48: Olivia Rodrigo | C48: 12878186 | D48: =(C48/1000*5) -> 64390.93 | E48: 44204 | F48: 44441 | G48: 0.16805556 | H48: POP | I48: SUA | J48: =IF(ISNUMBER(SEARCH("with",A48)),"Da","Nu") -> Nu
A49: Volando - Remix | B49: Mora | C49: 12598210 | D49: =(C49/1000*5) -> 62991.05 | E49: 44385 | F49: 44441 | G49: 0.18958333 | H49: LATIN | I49: Puerto Rico | J49: =IF(ISNUMBER(SEARCH("with",A49)),"Da","Nu") -> Nu
A50: 2055 | B50: Sleepy Hallow | C50: 12034127 | D50: =(C50/1000*5) -> 60170.635 | E50: 44300 | F50: 44441 | G50: 0.085416667 | H50: HIP-HOP/RAP | I50: Jamaica | J50: =IF(ISNUMBER(SEARCH("with",A50)),"Da","Nu") -> Nu
A51: Cúrame | B51: Rauw Alejandro | C51: 11797153 | D51: =(C51/1000*5) -> 58985.765 | E51: 44372 | F51: 44441 | G51: 0.11388889 | H51: LATIN URBAN | I51: Puerto Rico | J51: =IF(ISNUMBER(SEARCH("with",A51)),"Da","Nu") -> Nu
A52: Pure Souls | B52: Kanye West | C52: 11585806 | D52: =(C52/1000*5) -> 57929.03 | E52: 44437 | F52: 44441 | G52: 0.24861111 | H52: HIP-HOP/RAP | I52: SUA | J52: =IF(ISNUMBER(SEARCH("with",A52)),"Da","Nu") -> Nu
A53: Get Into It (Yuh) | B53: Doja Cat | C53: 11294620 | D53: =(C53/1000*5) -> 56473.1 | E53: 44372 | F53: 44441 | G53: 0.095833333 | H53: POP | I53: SUA | J53: =IF(ISNUMBER(SEARCH("with",A53)),"Da","Nu") -> Nu
A54: Donda | B54: Kanye West | C54: 11098736 | D54: =(C54/1000*5) -> 55493.68 | E54: 44437 | F54: 44441 | G54: 0.088888889 | H54: HIP-HOP/RAP | I54: SUA | J54: =IF(ISNUMBER(SEARCH("with",A54)),"Da","Nu") -> Nu
A55: Leave The Door Open | B55: Bruno Mars | C55: 11085219 | D55: =(C55/1000*5) -> 55426.095 | E55: 44260 | F55: 44441 | G55: 0.16805556 | H55: R&B/SOUL | I55: Puerto Rico | J55: =IF(ISNUMBER(SEARCH("with",A55)),"Da","Nu") -> Nu
A56: Sobrio | B56: Maluma | C56: 11037322 | D56: =(C56/1000*5) -> 55186.61 | E56: 44385 | F56: 44441 | G56: 0.13958333 | H56: LATIN URBAN | I56: Columbia | J56: =IF(ISNUMBER(SEARCH("with",A56)),"Da","Nu") -> Nu
A57: Entre Nosotros | B57: Tiago PZK | C57: 10951000 | D57: =(C57/1000*5) -> 54755 | E57: 44386 | F57: 44441 | G57: 0.13333333 | H57: RHYTHM & BLUES | I57: Argentina | J57: =IF(ISNUMBER(SEARCH("with",A57)),"Da","Nu") -> Nu
A58: Keep My Spirit Alive | B58: Kanye West | C58: 10913129 | D58: =(C58/1000*5) -> 54565.645 | E58: 44437 | F58: 44441 | G58: 0.15347222 | H58: HIP-HOP/RAP | I58: SUA | J58: =IF(ISNUMBER(SEARCH("with",A58)),"Da","Nu") -> Nu
A59: Jesus Lord | B59: Kanye West | C59: 10900265 | D59: =(C59/1000*5) -> 54501.325 | E59: 44437 | F59: 44441 | G59: 0.37361111 | H59: HIP-HOP/RAP | I59: SUA | J59: =IF(ISNUMBER(SEARCH("with",A59)),"Da","Nu") -> Nu
A60: happier | B60: Olivia Rodrigo | C60: 10837112 | D60: =(C60/1000*5) -> 54185.56 | E60: 44337 | F60: 44441 | G60: 0.12152778 | H60: POP | I60: SUA | J60: =IF(ISNUMBER(SEARCH("with",A60)),"Da","Nu") -> Nu
A61: Love Tonight - Edit | B61: Shouse | C61: 10655348 | D61: =(C61/1000*5) -> 53276.74 | E61: 43083 | F61: 44441 | G61: 0.16736111 | H61: ELECTRONIC | I61: Australia | J61: =IF(ISNUMBER(SEARCH("with",A61)),"Da","Nu") -> Nu
A62: Watermelon Sugar | B62: Harry Styles | C62: 10454615 | D62: =(C62/1000*5) -> 52273.075 | E62: 43812 | F62: 44441 | G62: 0.12013889 | H62: POP | I62: Marea Britanie | J62: =IF(ISNUMBER(SEARCH("with",A62)),"Da","Nu") -> Nu
... A183: Iko Iko (My Bestie) | B183: Justin Wellington | C183: 5593786 | D183: =(C183/1000*5) -> 27968.93 | E183: 44411 | F183: 44441 | G183: 0.23541667 | H183: POP | I183: Papua | J183: =IF(ISNUMBER(SEARCH("with",A183)),"Da","Nu") -> Nu
A184: 512 | B184: Mora | C184: 5574638 | D184: =(C184/1000*5) -> 27873.19 | E184: 44437 | F184: 44441 | G184: 0.095138889 | H184: ROCK | I184: Puerto Rico | J184: =IF(ISNUMBER(SEARCH("with",A184)),"Da","Nu") -> Nu
A185: Remember (and David Guetta) | B185: Becky Hill | C185: 5557982 | D185: =(C185/1000*5) -> 27789.91 | E185: 44351 | F185: 44441 | G185: 0.14444444 | H185: HIP-HOP/RAP | I185: Marea Britanie | J185: =IF(ISNUMBER(SEARCH("with",A185)),"Da","Nu") -> Nu
A186: REPEAT IT (with Gunna) | B186: Lil Tecca | C186: 5547450 | D186: =(C186/1000*5) -> 27737.25 | E186: 44274 | F186: 44441 | G186: 0.13819444 | H186: ROCK | I186: SUA | J186: =IF(ISNUMBER(SEARCH("with",A186)),"Da","Nu") -> Da
A187: Say You Won't Let Go | B187: James Arthur | C187: 5547420 | D187: =(C187/1000*5) -> 27737.1 | E187: 44460 | F187: 44441 | G187: 0.15694444 | H187: HIP-HOP/RAP | I187: Marea Britanie | J187: =IF(ISNUMBER(SEARCH("with",A187)),"Da","Nu") -> Nu
A188: Every Breath You Take | B188: The Police | C188: 5520749 | D188: =(C188/1000*5) -> 27603.745 | E188: 44377 | F188: 44441 | G188: 0.16527778 | H188: HIP-HOP/RAP | I188: Marea Britanie | J188: =IF(ISNUMBER(SEARCH("with",A188)),"Da","Nu") -> Nu
A189: HawÃ¡i | B189: Maluma | C189: 5502543 | D189: =(C189/1000*5) -> 27512.715 | E189: 44248 | F189: 44441 | G189: 0.15972222 | H189: HIP-HOP/RAP | I189: Columbia | J189: =IF(ISNUMBER(SEARCH("with",A189)),"Da","Nu") -> Nu
A190: Dreams - 2004 Remaster | B190: Fleetwood Mac | C190: 5477944 | D190: =(C190/1000*5) -> 27389.72 | E190: 44259 | F190: 44441 | G190: 0.10833333 | H190: HIP-HOP/RAP | I190: Marea Britanie | J190: =IF(ISNUMBER(SEARCH("with",A190)),"Da","Nu") -> Nu
...

Sheet 9.09.2021
A1: Numele Melodiei | B1: Artist | C1: Numar vizualizari | D1: Venituri (nr vizulizari/1000*5) | E1: Data Lansarii | F1: Aparitii in top 200 | G1: Durata Melodiei | H1: Genul de Muzica | I1: Nationalitatea Artistului | J1: Colaborare
A3: STAY (with Justin Bieber) | B3: The Kid LAROI | C3: 61385396 | D3: =(C3/1000*5) -> 306926.98 | E3: =VLOOKUP(A3,'2.09.2021'!A$3:'2.09.2021'!I$202,5,) -> 44386 | F3: 44448 | G3: =VLOOKUP(A3,'2.09.2021'!A$3:'2.09.2021'!I$202,7,) -> 0.097916667 | H3: =VLOOKUP(A3,'2.09.2021'!A$3:'2.09.2021'!I$202,8,) -> POP | I3: =VLOOKUP(A3,'2.09.2021'!A$3:'2.09.2021'!I$202,9,) -> Australia | J3: =IF(ISNUMBER(SEARCH("with",A3)),"Da","Nu") -> Da
A4: INDUSTRY BABY (with Jack Harlow) | B4: Lil Nas X | C4: 53085371 | D4: =(C4/1000*5) -> 265426.85 | E4: =VLOOKUP(A4,'2.09.2021'!A$3:'2.09.2021'!I$202,5,) -> 44400 | F4: 44448 | G4: =VLOOKUP(A4,'2.09.2021'!A$3:'2.09.2021'!I$202,7,) -> 0.14722222 | H4: =VLOOKUP(A4,'2.09.2021'!A$3:'2.09.2021'!I$202,8,) -> HIP-HOP/RAP | I4: =VLOOKUP(A4,'2.09.2021'!A$3:'2.09.2021'!I$202,9,) -> SUA | J4: =IF(ISNUMBER(SEARCH("with",A4)),"Da","Nu") -> Da
A5: THATS WHAT I WANT | B5: Lil Nas X | C5: 32546474 | D5: =(C5/1000*5) -> 162732.37 | E5: =VLOOKUP(A5,'30.09.2021'!A$3:'30.09.2021'!I$202,5,) -> 44316 | F5: 44448 | G5: =VLOOKUP(A5,'30.09.2021'!A$3:'30.09.2021'!I$202,7,) -> 0.18125 | H5: =VLOOKUP(A5,'30.09.2021'!A$3:'30.09.2021'!I$202,8,) -> POP | I5: =VLOOKUP(A5,'30.09.2021'!A$3:'30.09.2021'!I$202,9,) -> SUA | J5: =IF(ISNUMBER(SEARCH("with",A5)),"Da","Nu") -> Nu
A6: Heat Waves | B6: Glass Animals | C6: 31103477 | D6: =(C6/1000*5) -> 155517.39 | E6: =VLOOKUP(A6,'2.09.2021'!A$3:'2.09.2021'!I$202,5,) -> 44050 | F6: 44448 | G6: =VLOOKUP(A6,'2.09.2021'!A$3:'2.09.2021'!I$202,7,) -> 0.16527778 | H6: =VLOOKUP(A6,'2.09.2021'!A$3:'2.09.2021'!I$202,8,) -> POP | I6: =VLOOKUP(A6,'2.09.2021'!A$3:'2.09.2021'!I$202,9,) -> Marea Britanie | J6: =IF(ISNUMBER(SEARCH("with",A6)),"Da","Nu") -> Nu
A7: Bad Habits | B7: Ed Sheeran | C7: 30276896 | D7: =(C7/1000*5) -> 151384.48 | E7: =VLOOKUP(A7,'2.09.2021'!A$3:'2.09.2021'!I$202,5,) -> 44358 | F7: 44448 | G7: =VLOOKUP(A7,'2.09.2021'!A$3:'2.09.2021'!I$202,7,) -> 0.14722222 | H7: =VLOOKUP(A7,'2.09.2021'!A$3:'2.09.2021'!I$202,8,) -> POP | I7: =VLOOKUP(A7,'2.09.2021'!A$3:'2.09.2021'!I$202,9,) -> Marea Britanie | J7: =IF(ISNUMBER(SEARCH("with",A7)),"Da","Nu") -> Nu
A8: Pepas | B8: Farruko | C8: 30119703 | D8: =(C8/1000*5) -> 150598.52 | E8: =VLOOKUP(A8,'2.09.2021'!A$3:'2.09.2021'!I$202,5,) -> 44538 | F8: 44448 | G8: =VLOOKUP(A8,'2.09.2021'!A$3:'2.09.2021'!I$202,7,) -> 0.19930556 | H8: =VLOOKUP(A8,'2.09.2021'!A$3:'2.09.2021'!I$202,8,) -> LATIN URBAN | I8: =VLOOKUP(A8,'2.09.2021'!A$3:'2.09.2021'!I$202,9,) -> Puerto Rico | J8: =IF(ISNUMBER(SEARCH("with",A8)),"Da","Nu") -> Nu
A9: Woman | B9: Doja Cat | C9: 29648304 | D9: =(C9/1000*5) -> 148241.52 | E9: =VLOOKUP(A9,'2.09.2021'!A$3:'2.09.2021'!I$202,5,) -> 44374 | F9: 44448 | G9: =VLOOKUP(A9,'2.09.2021'!A$3:'2.09.2021'!I$202,7,) -> 0.10069444 | H9: =VLOOKUP(A9,'2.09.2021'!A$3:'2.09.2021'!I$202,8,) -> POP | I9: =VLOOKUP(A9,'2.09.2021'!A$3:'2.09.2021'!I$202,9,) -> SUA | J9: =IF(ISNUMBER(SEARCH("with",A9)),"Da","Nu") -> Nu
A10: MONTERO (Call Me By Your Name) | B10: Lil Nas X | C10: 28933084 | D10: =(C10/1000*5) -> 144665.42 | E10: =VLOOKUP(A10,'2.09.2021'!A$3:'2.09.2021'!I$202,5,) -> 44456 | F10: 44448 | G10: =VLOOKUP(A10,'2.09.2021'!A$3:'2.09.2021'!I$202,7,) -> 0.095138889 | H10: =VLOOKUP(A10,'2.09.2021'!A$3:'2.09.2021'!I$202,8,) -> POP | I10: =VLOOKUP(A10,'2.09.2021'!A$3:'2.09.2021'!I$202,9,) -> SUA | J10: =IF(ISNUMBER(SEARCH("with",A10)),"Da","Nu") -> Nu
A11: Shivers | B11: Ed Sheeran | C11: 27138539 | D11: =(C11/1000*5) -> 135692.7 | E11: =VLOOKUP(A11,'16.09.2021'!A$3:'16.09.2021'!I$202,5,) -> 44315 | F11: 44448 | G11: =VLOOKUP(A11,'16.09.2021'!A$3:'16.09.2021'!I$202,7,) -> 0.10555556 | H11: =VLOOKUP(A11,'16.09.2021'!A$3:'16.09.2021'!I$202,8,) -> POP | I11: =VLOOKUP(A11,'16.09.2021'!A$3:'16.09.2021'!I$202,9,) -> Marea Britanie | J11: =IF(ISNUMBER(SEARCH("with",A11)),"Da","Nu") -> Nu
A12: Beggin' | B12: Måneskin | C12: 26309445 | D12: =(C12/1000*5) -> 131547.23 | E12: =VLOOKUP(A12,'2.09.2021'!A$3:'2.09.2021'!I$202,5,) -> 43077 | F12: 44448 | G12: =VLOOKUP(A12,'2.09.2021'!A$3:'2.09.2021'!I$202,7,) -> 0.14652778 | H12: =VLOOKUP(A12,'2.09.2021'!A$3:'2.09.2021'!I$202,8,) -> ROCK | I12: =VLOOKUP(A12,'2.09.2021'!A$3:'2.09.2021'!I$202,9,) -> Italia | J12: =IF(ISNUMBER(SEARCH("with",A12)),"Da","Nu") -> Nu
A13: good 4 u | B13: Olivia Rodrigo | C13: 24943366 | D13: =(C13/1000*5) -> 124716.83 | E13: =VLOOKUP(A13,'2.09.2021'!A$3:'2.09.2021'!I$202,5,) -> 44337 | F13: 44448 | G13: =VLOOKUP(A13,'2.09.2021'!A$3:'2.09.2021'!I$202,7,) -> 0.12361111 | H13: =VLOOKUP(A13,'2.09.2021'!A$3:'2.09.2021'!I$202,8,) -> POP | I13: =VLOOKUP(A13,'2.09.2021'!A$3:'2.09.2021'!I$202,9,) -> SUA | J13: =IF(ISNUMBER(SEARCH("with",A13)),"Da","Nu") -> Nu
A14: Way 2 Sexy (with Future & Young Thug) | B14: Drake | C14: 23088866 | D14: =(C14/1000*5) -> 115444.33 | E14: =VLOOKUP(A14,'16.09.2021'!A$3:'16.09.2021'!I$202,5,) -> 44460 | F14: 44448 | G14: =VLOOKUP(A14,'16.09.2021'!A$3:'16.09.2021'!I$202,7,) -> 0.055555556 | H14: =VLOOKUP(A14,'16.09.2021'!A$3:'16.09.2021'!I$202,8,) -> HIP-HOP/RAP | I14: =VLOOKUP(A14,'16.09.2021'!A$3:'16.09.2021'!I$202,9,) -> Canada | J14: =IF(ISNUMBER(SEARCH("with",A14)),"Da","Nu") -> Da
A15: Need To Know | B15: Doja Cat | C15: 22506534 | D15: =(C15/1000*5) -> 112532.67 | E15: =VLOOKUP(A15,'2.09.2021'!A$3:'2.09.2021'!I$202,5,) -> 44371 | F15: 44448 | G15: =VLOOKUP(A15,'2.09.2021'!A$3:'2.09.2021'!I$202,7,) -> 0.14583333 | H15: =VLOOKUP(A15,'2.09.2021'!A$3:'2.09.2021'!I$202,8,) -> POP | I15: =VLOOKUP(A15,'2.09.2021'!A$3:'2.09.2021'!I$202,9,) -> SUA | J15: =IF(ISNUMBER(SEARCH("with",A15)),"Da","Nu") -> Nu
A16: Fair Trade (with Travis Scott) | B16: Drake | C16: 20658947 | D16: =(C16/1000*5) -> 103294.74 | E16: =VLOOKUP(A16,'16.09.2021'!A$3:'16.09.2021'!I$202,5,) -> 44460 | F16: 44448 | G16: =VLOOKUP(A16,'16.09.2021'!A$3:'16.09.2021'!I$202,7,) -> 0.14097222 | H16: =VLOOKUP(A16,'16.09.2021'!A$3:'16.09.2021'!I$202,8,) -> hIP-HOP/RAP | I16: =VLOOKUP(A16,'16.09.2021'!A$3:'16.09.2021'!I$202,9,) -> Canada | J16: =IF(ISNUMBER(SEARCH("with",A16)),"Da","Nu") -> Da
A17: Kiss Me More (with SZA) | B17: Doja Cat | C17: 19826752 | D17: =(C17/1000*5) -> 99133.76 | E17: =VLOOKUP(A17,'2.09.2021'!A$3:'2.09.2021'!I$202,5,) -> 44295 | F17: 44448 | G17: =VLOOKUP(A17,'2.09.2021'!A$3:'2.09.2021'!I$202,7,) -> 0.14444444 | H17: =VLOOKUP(A17,'2.09.2021'!A$3:'2.09.2021'!I$202,8,) -> POP | I17: =VLOOKUP(A17,'2.09.2021'!A$3:'2.09.2021'!I$202,9,) -> SUA | J17: =IF(ISNUMBER(SEARCH("with",A17)),"Da","Nu") -> Da
A18: Happier Than Ever | B18: Billie Eilish | C18: 19263184 | D18: =(C18/1000*5) -> 96315.92 | E18: =VLOOKUP(A18,'2.09.2021'!A$3:'2.09.2021'!I$202,5,) -> 44407 | F18: 44448 | G18: =VLOOKUP(A18,'2.09.2021'!A$3:'2.09.2021'!I$202,7,) -> 0.20694444 | H18: =VLOOKUP(A18,'2.09.2021'!A$3:'2.09.2021'!I$202,8,) -> ALTERNATIVE | I18: =VLOOKUP(A18,'2.09.2021'!A$3:'2.09.2021'!I$202,9,) -> SUA | J18: =IF(ISNUMBER(SEARCH("with",A18)),"Da","Nu") -> Nu
A19: Life Goes On | B19: Oliver Tree | C19: 18234742 | D19: =(C19/1000*5) -> 91173.71 | E19: =VLOOKUP(A19,'16.09.2021'!A$3:'16.09.2021'!I$202,5,) -> 44460 | F19: 44448 | G19: =VLOOKUP(A19,'16.09.2021'!A$3:'16.09.2021'!I$202,7,) -> 0.13958333 | H19: =VLOOKUP(A19,'16.09.2021'!A$3:'16.09.2021'!I$202,8,) -> POP | I19: =VLOOKUP(A19,'16.09.2021'!A$3:'16.09.2021'!I$202,9,) -> SUA | J19: =IF(ISNUMBER(SEARCH("with",A19)),"Da","Nu") -> Nu
A20: Cold Heart - PNAU Remix | B20: Elton John | C20: 17171664 | D20: =(C20/1000*5) -> 85858.32 | E20: =VLOOKUP(A20,'2.09.2021'!A$3:'2.09.2021'!I$202,5,) -> 44421 | F20: 44448 | G20: =VLOOKUP(A20,'2.09.2021'!A$3:'2.09.2021'!I$202,7,) -> 0.14027778 | H20: =VLOOKUP(A20,'2.09.2021'!A$3:'2.09.2021'!I$202,8,) -> POP | I20: =VLOOKUP(A20,'2.09.2021'!A$3:'2.09.2021'!I$202,9,) -> Marea Britanie | J20: =IF(ISNUMBER(SEARCH("with",A20)),"Da","Nu") -> Nu
A21: Yonaguni | B21: Bad Bunny | C21: 16613967 | D21: =(C21/1000*5) -> 83069.835 | E21: =VLOOKUP(A21,'2.09.2021'!A$3:'2.09.2021'!I$202,5,) -> 44351 | F21: 44448 | G21: =VLOOKUP(A21,'2.09.2021'!A$3:'2.09.2021'!I$202,7,) -> 0.14305556 | H21: =VLOOKUP(A21,'2.09.2021'!A$3:'2.09.2021'!I$202,8,) -> LATIN URBAN | I21: =VLOOKUP(A21,'2.09.2021'!A$3:'2.09.2021'!I$202,9,) -> Puerto Rico | J21: =IF(ISNUMBER(SEARCH("with",A21)),"Da","Nu") -> Nu
A22: Todo De Ti | B22: Rauw Alejandro | C22: 16491457 | D22: =(C22/1000*5) -> 82457.285 | E22: =VLOOKUP(A22,'2.09.2021'!A$3:'2.09.2021'!I$202,5,) -> 44338 | F22: 44448 | G22: =VLOOKUP(A22,'2.09.2021'!A$3:'2.09.2021'!I$202,7,) -> 0.13819444 | H22: =VLOOKUP(A22,'2.09.2021'!A$3:'2.09.2021'!I$202,8,) -> LATIN URBAN | I22: =VLOOKUP(A22,'2.09.2021'!A$3:'2.09.2021'!I$202,9,) -> Puerto Rico | J22: =IF(ISNUMBER(SEARCH("with",A22)),"Da","Nu") -> Nu
A23: Girls Want Girls (with Lil Baby) | B23: Drake | C23: 15925804 | D23: =(C23/1000*5) -> 79629.02 | E23: =VLOOKUP(A23,'16.09.2021'!A$3:'16.09.2021'!I$202,5,) -> 44460 | F23: 44448 | G23: =VLOOKUP(A23,'16.09.2021'!A$3:'16.09.2021'!I$202,7,) -> 0.085416667 | H23: =VLOOKUP(A23,'16.09.2021'!A$3:'16.09.2021'!I$202,8,) -> hIP-HOP/RAP | I23: =VLOOKUP(A23,'16.09.2021'!A$3:'16.09.2021'!I$202,9,) -> Canada | J23: =IF(ISNUMBER(SEARCH("with",A23)),"Da","Nu") -> Da
A24: Knife Talk (with 21 Savage ft. Project Pat) | B24: Drake | C24: 15905936 | D24: =(C24/1000*5) -> 79529.68 | E24: =VLOOKUP(A24,'16.09.2021'!A$3:'16.09.2021'!I$202,5,) -> 44460 | F24: 44448 | G24: =VLOOKUP(A24,'16.09.2021'!A$3:'16.09.2021'!I$202,7,) -> 0.16736111 | H24: =VLOOKUP(A24,'16.09.2021'!A$3:'16.09.2021'!I$202,8,) -> HIP-HOP/RAP | I24: =VLOOKUP(A24,'16.09.2021'!A$3:'16.09.2021'!I$202,9,) -> Canada | J24: =IF(ISNUMBER(SEARCH("with",A24)),"Da","Nu") -> Da
A25: Volví | B25: Aventura | C25: 15694072 | D25: =(C25/1000*5) -> 78470.36 | E25: =VLOOKUP(A25,'16.09.2021'!A$3:'16.09.2021'!I$202,5,) -> 44411 | F25: 44448 | G25: =VLOOKUP(A25,'16.09.2021'!A$3:'16.09.2021'!I$202,7,) -> 0.15972222 | H25: =VLOOKUP(A25,'16.09.2021'!A$3:'16.09.2021'!I$202,8,) -> LATIN URBAN | I25: =VLOOKUP(A25,'16.09.2021'!A$3:'16.09.2021'!I$202,9,) -> Republica Dominicană | J25: =IF(ISNUMBER(SEARCH("with",A25)),"Da","Nu") -> Nu
A26: LALISA | B26: LISA | C26: 15577524 | D26: =(C26/1000*5) -> 77887.62 | E26: =VLOOKUP(A26,'16.09.2021'!A$3:'16.09.2021'!I$202,5,) -> 44257 | F26: 44448 | G26: =VLOOKUP(A26,'16.09.2021'!A$3:'16.09.2021'!I$202,7,) -> 0.13888889 | H26: =VLOOKUP(A26,'16.09.2021'!A$3:'16.09.2021'!I$202,8,) -> HIP-HOP/RAP | I26: =VLOOKUP(A26,'16.09.2021'!A$3:'16.09.2021'!I$202,9,) -> Tailanda | J26: =IF(ISNUMBER(SEARCH("with",A26)),"Da","Nu") -> Nu
A27: Hurricane | B27: Kanye West | C27: 15167133 | D27: =(C27/1000*5) -> 75835.665 | E27: =VLOOKUP(A27,'2.09.2021'!A$3:'2.09.2021'!I$202,5,) -> 44416 | F27: 44448 | G27: =VLOOKUP(A27,'2.09.2021'!A$3:'2.09.2021'!I$202,7,) -> 0.16875 | H27: =VLOOKUP(A27,'2.09.2021'!A$3:'2.09.2021'!I$202,8,) -> HIP-HOP/RAP | I27: =VLOOKUP(A27,'2.09.2021'!A$3:'2.09.2021'!I$202,9,) -> SUA | J27: =IF(ISNUMBER(SEARCH("with",A27)),"Da","Nu") -> Nu
A28: traitor | B28: Olivia Rodrigo | C28: 15165886 | D28: =(C28/1000*5) -> 75829.43 | E28: =VLOOKUP(A28,'2.09.2021'!A$3:'2.09.2021'!I$202,5,) -> 44337 | F28: 44448 | G28: =VLOOKUP(A28,'2.09.2021'!A$3:'2.09.2021'!I$202,7,) -> 0.15902778 | H28: =VLOOKUP(A28,'2.09.2021'!A$3:'2.09.2021'!I$202,8,) -> POP | I28: =VLOOKUP(A28,'2.09.2021'!A$3:'2.09.2021'!I$202,9,) -> SUA | J28: =IF(ISNUMBER(SEARCH("with",A28)),"Da","Nu") -> Nu
A29: Levitating (with DaBaby) | B29: Dua Lipa | C29: 15154174 | D29: =(C29/1000*5) -> 75770.87 | E29: =VLOOKUP(A29,'2.09.2021'!A$3:'2.09.2021'!I$202,5,) -> 43917 | F29: 44448 | G29: =VLOOKUP(A29,'2.09.2021'!A$3:'2.09.2021'!I$202,7,) -> 0.14097222 | H29: =VLOOKUP(A29,'2.09.2021'!A$3:'2.09.2021'!I$202,8,) -> POP | I29: =VLOOKUP(A29,'2.09.2021'!A$3:'2.09.2021'!I$202,9,) -> Marea Britanie | J29: =IF(ISNUMBER(SEARCH("with",A29)),"Da","Nu") -> Da
A30: In Da Getto | B30: J Balvin | C30: 14735208 | D30: =(C30/1000*5) -> 73676.04 | E30: =VLOOKUP(A30,'2.09.2021'!A$3:'2.09.2021'!I$202,5,) -> 44379 | F30: 44448 | G30: =VLOOKUP(A30,'2.09.2021'!A$3:'2.09.2021'!I$202,7,) -> 0.090277778 | H30: =VLOOKUP(A30,'2.09.2021'!A$3:'2.09.2021'!I$202,8,) -> LATIN URBAN | I30: =VLOOKUP(A30,'2.09.2021'!A$3:'2.09.2021'!I$202,9,) -> Columbia | J30: =IF(ISNUMBER(SEARCH("with",A30)),"Da","Nu") -> Nu
A31: Wildest Dreams (Taylor's Version) | B31: Taylor Swift | C31: 14592123 | D31: =(C31/1000*5) -> 72960.615 | E31: =VLOOKUP(A31,'30.09.2021'!A$3:'30.09.2021'!I$202,5,) -> 44370 | F31: 44448 | G31: =VLOOKUP(A31,'30.09.2021'!A$3:'30.09.2021'!I$202,7,) -> 0.11527778 | H31: =VLOOKUP(A31,'30.09.2021'!A$3:'30.09.2021'!I$202,8,) -> POP | I31: =VLOOKUP(A31,'30.09.2021'!A$3:'30.09.2021'!I$202,9,) -> SUA | J31: =IF(ISNUMBER(SEARCH("with",A31)),"Da","Nu") -> Nu
A32: Peaches (with Daniel Caesar & Giveon) | B32: Justin Bieber | C32: 14173474 | D32: =(C32/1000*5) -> 70867.37 | E32: =VLOOKUP(A32,'2.09.2021'!A$3:'2.09.2021'!I$202,5,) -> 44274 | F32: 44448 | G32: =VLOOKUP(A32,'2.09.2021'!A$3:'2.09.2021'!I$202,7,) -> 0.1375 | H32: =VLOOKUP(A32,'2.09.2021'!A$3:'2.09.2021'!I$202,8,) -> POP | I32: =VLOOKUP(A32,'2.09.2021'!A$3:'2.09.2021'!I$202,9,) -> Canada | J32: =IF(ISNUMBER(SEARCH("with",A32)),"Da","Nu") -> Da
A33: Take My Breath | B33: The Weeknd | C33: 13898588 | D33: =(C33/1000*5) -> 69492.94 | E33: =VLOOKUP(A33,'2.09.2021'!A$3:'2.09.2021'!I$202,5,) -> 44414 | F33: 44448 | G33: =VLOOKUP(A33,'2.09.2021'!A$3:'2.09.2021'!I$202,7,) -> 0.15277778 | H33: =VLOOKUP(A33,'2.09.2021'!A$3:'2.09.2021'!I$202,8,) -> R&B/SOUL | I33: =VLOOKUP(A33,'2.09.2021'!A$3:'2.09.2021'!I$202,9,) -> Canada | J33: =IF(ISNUMBER(SEARCH("with",A33)),"Da","Nu") -> Nu
A34: love nwantiti (ah ah ah) | B34: CKay | C34: 13833060 | D34: =(C34/1000*5) -> 69165.3 | E34: =VLOOKUP(A34,'30.09.2021'!A$3:'30.09.2021'!I$202,5,) -> 44337 | F34: 44448 | G34: =VLOOKUP(A34,'30.09.2021'!A$3:'30.09.2021'!I$202,7,) -> 0.10138889 | H34: =VLOOKUP(A34,'30.09.2021'!A$3:'30.09.2021'!I$202,8,) -> AFROBEATS | I34: =VLOOKUP(A34,'30.09.2021'!A$3:'30.09.2021'!I$202,9,) -> Africa | J34: =IF(ISNUMBER(SEARCH("with",A34)),"Da","Nu") -> Nu
A35: Qué Más Pues? | B35: J Balvin | C35: 13614671 | D35: =(C35/1000*5) -> 68073.355 | E35: =VLOOKUP(A35,'2.09.2021'!A$3:'2.09.2021'!I$202,5,) -> 44344 | F35: 44448 | G35: =VLOOKUP(A35,'2.09.2021'!A$3:'2.09.2021'!I$202,7,) -> 0.15069444 | H35: =VLOOKUP(A35,'2.09.2021'!A$3:'2.09.2021'!I$202,8,) -> LATIN URBAN | I35: =VLOOKUP(A35,'2.09.2021'!A$3:'2.09.2021'!I$202,9,) -> Columbia | J35: =IF(ISNUMBER(SEARCH("with",A35)),"Da","Nu") -> Nu
A36: Meet Me At Our Spot | B36: THE ANXIETY | C36: 13473188 | D36: =(C36/1000*5) -> 67365.94 | E36: =VLOOKUP(A36,'30.09.2021'!A$3:'30.09.2021'!I$202,5,) -> 44347 | F36: 44448 | G36: =VLOOKUP(A36,'30.09.2021'!A$3:'30.09.2021'!I$202,7,) -> 0.15625 | H36: =VLOOKUP(A36,'30.09.2021'!A$3:'30.09.2021'!I$202,8,) -> POP | I36: =VLOOKUP(A36,'30.09.2021'!A$3:'30.09.2021'!I$202,9,) -> SUA | J36: =IF(ISNUMBER(SEARCH("with",A36)),"Da","Nu") -> Nu
A37: I WANNA BE YOUR SLAVE | B37: Måneskin | C37: 13194771 | D37: =(C37/1000*5) -> 65973.855 | E37: =VLOOKUP(A37,'2.09.2021'!A$3:'2.09.2021'!I$202,5,) -> 44274 | F37: 44448 | G37: =VLOOKUP(A37,'2.09.2021'!A$3:'2.09.2021'!I$202,7,) -> 0.12013889 | H37: =VLOOKUP(A37,'2.09.2021'!A$3:'2.09.2021'!I$202,8,) -> ROCK | I37: =VLOOKUP(A37,'2.09.2021'!A$3:'2.09.2021'!I$202,9,) -> Italia | J37: =IF(ISNUMBER(SEARCH("with",A37)),"Da","Nu") -> Nu
A38: Blinding Lights | B38: The Weeknd | C38: 13014956 | D38: =(C38/1000*5) -> 65074.78 | E38: =VLOOKUP(A38,'2.09.2021'!A$3:'2.09.2021'!I$202,5,) -> 43798 | F38: 44448 | G38: =VLOOKUP(A38,'2.09.2021'!A$3:'2.09.2021'!I$202,7,) -> 0.13958333 | H38: =VLOOKUP(A38,'2.09.2021'!A$3:'2.09.2021'!I$202,8,) -> R&B/SOUL | I38: =VLOOKUP(A38,'2.09.2021'!A$3:'2.09.2021'!I$202,9,) -> Canada | J38: =IF(ISNUMBER(SEARCH("with",A38)),"Da","Nu") -> Nu
A39: Save Your Tears (with Ariana Grande) (Remix) | B39: The Weeknd | C39: 12579776 | D39: =(C39/1000*5) -> 62898.88 | E39: =VLOOKUP(A39,'2.09.2021'!A$3:'2.09.2021'!I$202,5,) -> 43910 | F39: 44448 | G39: =VLOOKUP(A39,'2.09.2021'!A$3:'2.09.2021'!I$202,7,) -> 0.14930556 | H39: =VLOOKUP(A39,'2.09.2021'!A$3:'2.09.2021'!I$202,8,) -> R&B/SOUL | I39: =VLOOKUP(A39,'2.09.2021'!A$3:'2.09.2021'!I$202,9,) -> Canada | J39: =IF(ISNUMBER(SEARCH("with",A39)),"Da","Nu") -> Da
A40: SCOOP (with Doja Cat) | B40: Lil Nas X | C40: 12520878 | D40: =(C40/1000*5) -> 62604.39 | E40: =VLOOKUP(A40,'30.09.2021'!A$3:'30.09.2021'!I$202,5,) -> 44476 | F40: 44448 | G40: =VLOOKUP(A40,'30.09.2021'!A$3:'30.09.2021'!I$202,7,) -> 0.22430556 | H40: =VLOOKUP(A40,'30.09.2021'!A$3:'30.09.2021'!I$202,8,) -> HIP-HOP/RAP | I40: =VLOOKUP(A40,'30.09.2021'!A$3:'30.09.2021'!I$202,9,) -> SUA | J40: =IF(ISNUMBER(SEARCH("with",A40)),"Da","Nu") -> Da
A41: 2055 | B41: Sleepy Hallow | C41: 12485782 | D41: =(C41/1000*5) -> 62428.91 | E41: =VLOOKUP(A41,'2.09.2021'!A$3:'2.09.2021'!I$202,5,) -> 44300 | F41: 44448 | G41: =VLOOKUP(A41,'2.09.2021'!A$3:'2.09.2021'!I$202,7,) -> 0.085416667 | H41: =VLOOKUP(A41,'2.09.2021'!A$3:'2.09.2021'!I$202,8,) -> HIP-HOP/RAP | I41: =VLOOKUP(A41,'2.09.2021'!A$3:'2.09.2021'!I$202,9,) -> Jamaica | J41: =IF(ISNUMBER(SEARCH("with",A41)),"Da","Nu") -> Nu
...

Sheet 16.09.2021
A1: Numele Melodiei | B1: Artist | C1: Numar vizualizari | D1: Venituri (nr vizulizari/1000*5) | E1: Data Lansarii | F1: Aparitii in top 200 | G1: Durata Melodiei | H1: Genul de Muzica | I1: Nationalitatea Artistului | J1: Colaborare
A3: STAY (with Justin Bieber) | B3: The Kid LAROI | C3: 62413082 | D3: =(C3/1000*5) -> 312065.41 | E3: =VLOOKUP(A3,'2.09.2021'!A$3:'2.09.2021'!I$202,5,) -> 44386 | F3: 44455 | G3: =VLOOKUP(A3,'2.09.2021'!A$3:'2.09.2021'!I$202,7,) -> 0.097916667 | H3: =VLOOKUP(A3,'2.09.2021'!A$3:'2.09.2021'!I$202,8,) -> POP | I3: =VLOOKUP(A3,'2.09.2021'!A$3:'2.09.2021'!I$202,9,) -> Australia | J3: =IF(ISNUMBER(SEARCH("with",A3)),"Da","Nu") -> Da
A4: INDUSTRY BABY (with Jack Harlow) | B4: Lil Nas X | C4: 41902868 | D4: =(C4/1000*5) -> 209514.34 | E4: =VLOOKUP(A4,'2.09.2021'!A$3:'2.09.2021'!I$202,5,) -> 44400 | F4: 44455 | G4: =VLOOKUP(A4,'2.09.2021'!A$3:'2.09.2021'!I$202,7,) -> 0.14722222 | H4: =VLOOKUP(A4,'2.09.2021'!A$3:'2.09.2021'!I$202,8,) -> HIP-HOP/RAP | I4: =VLOOKUP(A4,'2.09.2021'!A$3:'2.09.2021'!I$202,9,) -> SUA | J4: =IF(ISNUMBER(SEARCH("with",A4)),"Da","Nu") -> Da
A5: Bad Habits | B5: Ed Sheeran | C5: 31351285 | D5: =(C5/1000*5) -> 156756.42 | E5: =VLOOKUP(A5,'2.09.2021'!A$3:'2.09.2021'!I$202,5,) -> 44358 | F5: 44455 | G5: =VLOOKUP(A5,'2.09.2021'!A$3:'2.09.2021'!I$202,7,) -> 0.14722222 | H5: =VLOOKUP(A5,'2.09.2021'!A$3:'2.09.2021'!I$202,8,) -> POP | I5: =VLOOKUP(A5,'2.09.2021'!A$3:'2.09.2021'!I$202,9,) -> Marea Britanie | J5: =IF(ISNUMBER(SEARCH("with",A5)),"Da","Nu") -> Nu
A6: Pepas | B6: Farruko | C6: 29676719 | D6: =(C6/1000*5) -> 148383.6 | E6: =VLOOKUP(A6,'2.09.2021'!A$3:'2.09.2021'!I$202,5,) -> 44538 | F6: 44455 | G6: =VLOOKUP(A6,'2.09.2021'!A$3:'2.09.2021'!I$202,7,) -> 0.19930556 | H6: =VLOOKUP(A6,'2.09.2021'!A$3:'2.09.2021'!I$202,8,) -> LATIN URBAN | I6: =VLOOKUP(A6,'2.09.2021'!A$3:'2.09.2021'!I$202,9,) -> Puerto Rico | J6: =IF(ISNUMBER(SEARCH("with",A6)),"Da","Nu") -> Nu
A7: Heat Waves | B7: Glass Animals | C7: 28688699 | D7: =(C7/1000*5) -> 143443.49 | E7: =VLOOKUP(A7,'2.09.2021'!A$3:'2.09.2021'!I$202,5,) -> 44050 | F7: 44455 | G7: =VLOOKUP(A7,'2.09.2021'!A$3:'2.09.2021'!I$202,7,) -> 0.16527778 | H7: =VLOOKUP(A7,'2.09.2021'!A$3:'2.09.2021'!I$202,8,) -> POP | I7: =VLOOKUP(A7,'2.09.2021'!A$3:'2.09.2021'!I$202,9,) -> Marea Britanie | J7: =IF(ISNUMBER(SEARCH("with",A7)),"Da","Nu") -> Nu
A8: Woman | B8: Doja Cat | C8: 28542372 | D8: =(C8/1000*5) -> 142711.86 | E8: =VLOOKUP(A8,'2.09.2021'!A$3:'2.09.2021'!I$202,5,) -> 44374 | F8: 44455 | G8: =VLOOKUP(A8,'2.09.2021'!A$3:'2.09.2021'!I$202,7,) -> 0.10069444 | H8: =VLOOKUP(A8,'2.09.2021'!A$3:'2.09.2021'!I$202,8,) -> POP | I8: =VLOOKUP(A8,'2.09.2021'!A$3:'2.09.2021'!I$202,9,) -> SUA | J8: =IF(ISNUMBER(SEARCH("with",A8)),"Da","Nu") -> Nu
A9: Beggin' | B9: Måneskin | C9: 26772173 | D9: =(C9/1000*5) -> 133860.86 | E9: =VLOOKUP(A9,'2.09.2021'!A$3:'2.09.2021'!I$202,5,) -> 43077 | F9: 44455 | G9: =VLOOKUP(A9,'2.09.2021'!A$3:'2.09.2021'!I$202,7,) -> 0.14652778 | H9: =VLOOKUP(A9,'2.09.2021'!A$3:'2.09.2021'!I$202,8,) -> ROCK | I9: =VLOOKUP(A9,'2.09.2021'!A$3:'2.09.2021'!I$202,9,) -> Italia | J9: =IF(ISNUMBER(SEARCH("with",A9)),"Da","Nu") -> Nu
A10: good 4 u | B10: Olivia Rodrigo | C10: 25414611 | D10: =(C10/1000*5) -> 127073.06 | E10: =VLOOKUP(A10,'2.09.2021'!A$3:'2.09.2021'!I$202,5,) -> 44337 | F10: 44455 | G10: =VLOOKUP(A10,'2.09.2021'!A$3:'2.09.2021'!I$202,7,) -> 0.12361111 | H10: =VLOOKUP(A10,'2.09.2021'!A$3:'2.09.2021'!I$202,8,) -> POP | I10: =VLOOKUP(A10,'2.09.2021'!A$3:'2.09.2021'!I$202,9,) -> SUA | J10: =IF(ISNUMBER(SEARCH("with",A10)),"Da","Nu") -> Nu
A11: Fair Trade (with Travis Scott) | B11: Drake | C11: 25297983 | D11: =(C11/1000*5) -> 126489.92 | E11: =VLOOKUP(A11,'23.09.2021'!A$3:'23.09.2021'!I$202,5,) -> 44460 | F11: 44455 | G11: =VLOOKUP(A11,'23.09.2021'!A$3:'23.09.2021'!I$202,7,) -> 0.14097222 | H11: =VLOOKUP(A11,'23.09.2021'!A$3:'23.09.2021'!I$202,8,) -> hIP-HOP/RAP | I11: =VLOOKUP(A11,'23.09.2021'!A$3:'23.09.2021'!I$202,9,) -> Canada | J11: =IF(ISNUMBER(SEARCH("with",A11)),"Da","Nu") -> Da
A12: Way 2 Sexy (with Future & Young Thug) | B12: Drake | C12: 24928604 | D12: =(C12/1000*5) -> 124643.02 | E12: =VLOOKUP(A12,'23.09.2021'!A$3:'23.09.2021'!I$202,5,) -> 44460 | F12: 44455 | G12: =VLOOKUP(A12,'23.09.2021'!A$3:'23.09.2021'!I$202,7,) -> 0.055555556 | H12: =VLOOKUP(A12,'23.09.2021'!A$3:'23.09.2021'!I$202,8,) -> HIP-HOP/RAP | I12: =VLOOKUP(A12,'23.09.2021'!A$3:'23.09.2021'!I$202,9,) -> Canada | J12: =IF(ISNUMBER(SEARCH("with",A12)),"Da","Nu") -> Da
A13: Shivers | B13: Ed Sheeran | C13: 23729735 | D13: =(C13/1000*5) -> 118648.68 | E13: =VLOOKUP(A13,'30.09.2021'!A$3:'30.09.2021'!I$202,5,) -> 44315 | F13: 44455 | G13: =VLOOKUP(A13,'30.09.2021'!A$3:'30.09.2021'!I$202,7,) -> 0.10555556 | H13: =VLOOKUP(A13,'30.09.2021'!A$3:'30.09.2021'!I$202,8,) -> POP | I13: =VLOOKUP(A13,'30.09.2021'!A$3:'30.09.2021'!I$202,9,) -> Marea Britanie | J13: =IF(ISNUMBER(SEARCH("with",A13)),"Da","Nu") -> Nu
A14: Girls Want Girls (with Lil Baby) | B14: Drake | C14: 23379545 | D14: =(C14/1000*5) -> 116897.72 | E14: =VLOOKUP(A14,'23.09.2021'!A$3:'23.09.2021'!I$202,5,) -> 44460 | F14: 44455 | G14: =VLOOKUP(A14,'23.09.2021'!A$3:'23.09.2021'!I$202,7,) -> 0.085416667 | H14: =VLOOKUP(A14,'23.09.2021'!A$3:'23.09.2021'!I$202,8,) -> hIP-HOP/RAP | I14: =VLOOKUP(A14,'23.09.2021'!A$3:'23.09.2021'!I$202,9,) -> Canada | J14: =IF(ISNUMBER(SEARCH("with",A14)),"Da","Nu") -> Da
A15: Need To Know | B15: Doja Cat | C15: 23196486 | D15: =(C15/1000*5) -> 115982.43 | E15: =VLOOKUP(A15,'2.09.2021'!A$3:'2.09.2021'!I$202,5,) -> 44371 | F15: 44455 | G15: =VLOOKUP(A15,'2.09.2021'!A$3:'2.09.2021'!I$202,7,) -> 0.14583333 | H15: =VLOOKUP(A15,'2.09.2021'!A$3:'2.09.2021'!I$202,8,) -> POP | I15: =VLOOKUP(A15,'2.09.2021'!A$3:'2.09.2021'!I$202,9,) -> SUA | J15: =IF(ISNUMBER(SEARCH("with",A15)),"Da","Nu") -> Nu
A16: MONTERO (Call Me By Your Name) | B16: Lil Nas X | C16: 20710480 | D16: =(C16/1000*5) -> 103552.4 | E16: =VLOOKUP(A16,'2.09.2021'!A$3:'2.09.2021'!I$202,5,) -> 44456 | F16: 44455 | G16: =VLOOKUP(A16,'2.09.2021'!A$3:'2.09.2021'!I$202,7,) -> 0.095138889 | H16: =VLOOKUP(A16,'2.09.2021'!A$3:'2.09.2021'!I$202,8,) -> POP | I16: =VLOOKUP(A16,'2.09.2021'!A$3:'2.09.2021'!I$202,9,) -> SUA | J16: =IF(ISNUMBER(SEARCH("with",A16)),"Da","Nu") -> Nu
A17: Kiss Me More (with SZA) | B17: Doja Cat | C17: 20170105 | D17: =(C17/1000*5) -> 100850.52 | E17: =VLOOKUP(A17,'2.09.2021'!A$3:'2.09.2021'!I$202,5,) -> 44295 | F17: 44455 | G17: =VLOOKUP(A17,'2.09.2021'!A$3:'2.09.2021'!I$202,7,) -> 0.14444444 | H17: =VLOOKUP(A17,'2.09.2021'!A$3:'2.09.2021'!I$202,8,) -> POP | I17: =VLOOKUP(A17,'2.09.2021'!A$3:'2.09.2021'!I$202,9,) -> SUA | J17: =IF(ISNUMBER(SEARCH("with",A17)),"Da","Nu") -> Da
A18: Happier Than Ever | B18: Billie Eilish | C18: 19664713 | D18: =(C18/1000*5) -> 98323.565 | E18: =VLOOKUP(A18,'2.09.2021'!A$3:'2.09.2021'!I$202,5,) -> 44407 | F18: 44455 | G18: =VLOOKUP(A18,'2.09.2021'!A$3:'2.09.2021'!I$202,7,) -> 0.20694444 | H18: =VLOOKUP(A18,'2.09.2021'!A$3:'2.09.2021'!I$202,8,) -> ALTERNATIVE | I18: =VLOOKUP(A18,'2.09.2021'!A$3:'2.09.2021'!I$202,9,) -> SUA | J18: =IF(ISNUMBER(SEARCH("with",A18)),"Da","Nu") -> Nu
A19: Hurricane | B19: Kanye West | C19: 19370230 | D19: =(C19/1000*5) -> 96851.15 | E19: =VLOOKUP(A19,'2.09.2021'!A$3:'2.09.2021'!I$202,5,) -> 44416 | F19: 44455 | G19: =VLOOKUP(A19,'2.09.2021'!A$3:'2.09.2021'!I$202,7,) -> 0.16875 | H19: =VLOOKUP(A19,'2.09.2021'!A$3:'2.09.2021'!I$202,8,) -> HIP-HOP/RAP | I19: =VLOOKUP(A19,'2.09.2021'!A$3:'2.09.2021'!I$202,9,) -> SUA | J19: =IF(ISNUMBER(SEARCH("with",A19)),"Da","Nu") -> Nu
A20: LALISA | B20: LISA | C20: 18455241 | D20: =(C20/1000*5) -> 92276.205 | E20: =VLOOKUP(A20,'30.09.2021'!A$3:'30.09.2021'!I$202,5,) -> 44257 | F20: 44455 | G20: =VLOOKUP(A20,'30.09.2021'!A$3:'30.09.2021'!I$202,7,) -> 0.13888889 | H20: =VLOOKUP(A20,'30.09.2021'!A$3:'30.09.2021'!I$202,8,) -> HIP-HOP/RAP | I20: =VLOOKUP(A20,'30.09.2021'!A$3:'30.09.2021'!I$202,9,) -> Tailanda | J20: =IF(ISNUMBER(SEARCH("with",A20)),"Da","Nu") -> Nu
A21: Knife Talk (with 21 Savage ft. Project Pat) | B21: Drake | C21: 18375341 | D21: =(C21/1000*5) -> 91876.705 | E21: =VLOOKUP(A21,'23.09.2021'!A$3:'23.09.2021'!I$202,5,) -> 44460 | F21: 44455 | G21: =VLOOKUP(A21,'23.09.2021'!A$3:'23.09.2021'!I$202,7,) -> 0.16736111 | H21: =VLOOKUP(A21,'23.09.2021'!A$3:'23.09.2021'!I$202,8,) -> HIP-HOP/RAP | I21: =VLOOKUP(A21,'23.09.2021'!A$3:'23.09.2021'!I$202,9,) -> Canada | J21: =IF(ISNUMBER(SEARCH("with",A21)),"Da","Nu") -> Da
A22: Todo De Ti | B22: Rauw Alejandro | C22: 18022876 | D22: =(C22/1000*5) -> 90114.38 | E22: =VLOOKUP(A22,'2.09.2021'!A$3:'2.09.2021'!I$202,5,) -> 44338 | F22: 44455 | G22: =VLOOKUP(A22,'2.09.2021'!A$3:'2.09.2021'!I$202,7,) -> 0.13819444 | H22: =VLOOKUP(A22,'2.09.2021'!A$3:'2.09.2021'!I$202,8,) -> LATIN URBAN | I22: =VLOOKUP(A22,'2.09.2021'!A$3:'2.09.2021'!I$202,9,) -> Puerto Rico | J22: =IF(ISNUMBER(SEARCH("with",A22)),"Da","Nu") -> Nu
A23: Yonaguni | B23: Bad Bunny | C23: 17195763 | D23: =(C23/1000*5) -> 85978.815 | E23: =VLOOKUP(A23,'2.09.2021'!A$3:'2.09.2021'!I$202,5,) -> 44351 | F23: 44455 | G23: =VLOOKUP(A23,'2.09.2021'!A$3:'2.09.2021'!I$202,7,) -> 0.14305556 | H23: =VLOOKUP(A23,'2.09.2021'!A$3:'2.09.2021'!I$202,8,) -> LATIN URBAN | I23: =VLOOKUP(A23,'2.09.2021'!A$3:'2.09.2021'!I$202,9,) -> Puerto Rico | J23: =IF(ISNUMBER(SEARCH("with",A23)),"Da","Nu") -> Nu
A24: Volví | B24: Aventura | C24: 16342344 | D24: =(C24/1000*5) -> 81711.72 | E24: =VLOOKUP(A24,'2.09.2021'!A$3:'2.09.2021'!I$202,5,) -> 44411 | F24: 44455 | G24: =VLOOKUP(A24,'2.09.2021'!A$3:'2.09.2021'!I$202,7,) -> 0.15972222 | H24: =VLOOKUP(A24,'2.09.2021'!A$3:'2.09.2021'!I$202,8,) -> LATIN URBAN | I24: =VLOOKUP(A24,'2.09.2021'!A$3:'2.09.2021'!I$202,9,) -> Republica Dominicană | J24: =IF(ISNUMBER(SEARCH("with",A24)),"Da","Nu") -> Nu
A25: In Da Getto | B25: J Balvin | C25: 15971386 | D25: =(C25/1000*5) -> 79856.93 | E25: =VLOOKUP(A25,'2.09.2021'!A$3:'2.09.2021'!I$202,5,) -> 44379 | F25: 44455 | G25: =VLOOKUP(A25,'2.09.2021'!A$3:'2.09.2021'!I$202,7,) -> 0.090277778 | H25: =VLOOKUP(A25,'2.09.2021'!A$3:'2.09.2021'!I$202,8,) -> LATIN URBAN | I25: =VLOOKUP(A25,'2.09.2021'!A$3:'2.09.2021'!I$202,9,) -> Columbia | J25: =IF(ISNUMBER(SEARCH("with",A25)),"Da","Nu") -> Nu
A26: Qué Más Pues? | B26: J Balvin | C26: 15384428 | D26: =(C26/1000*5) -> 76922.14 | E26: =VLOOKUP(A26,'2.09.2021'!A$3:'2.09.2021'!I$202,5,) -> 44344 | F26: 44455 | G26: =VLOOKUP(A26,'2.09.2021'!A$3:'2.09.2021'!I$202,7,) -> 0.15069444 | H26: =VLOOKUP(A26,'2.09.2021'!A$3:'2.09.2021'!I$202,8,) -> LATIN URBAN | I26: =VLOOKUP(A26,'2.09.2021'!A$3:'2.09.2021'!I$202,9,) -> Columbia | J26: =IF(ISNUMBER(SEARCH("with",A26)),"Da","Nu") -> Nu
A27: Levitating (with DaBaby) | B27: Dua Lipa | C27: 15279109 | D27: =(C27/1000*5) -> 76395.545 | E27: =VLOOKUP(A27,'2.09.2021'!A$3:'2.09.2021'!I$202,5,) -> 43917 | F27: 44455 | G27: =VLOOKUP(A27,'2.09.2021'!A$3:'2.09.2021'!I$202,7,) -> 0.14097222 | H27: =VLOOKUP(A27,'2.09.2021'!A$3:'2.09.2021'!I$202,8,) -> POP | I27: =VLOOKUP(A27,'2.09.2021'!A$3:'2.09.2021'!I$202,9,) -> Marea Britanie | J27: =IF(ISNUMBER(SEARCH("with",A27)),"Da","Nu") -> Da
A28: traitor | B28: Olivia Rodrigo | C28: 14922433 | D28: =(C28/1000*5) -> 74612.165 | E28: =VLOOKUP(A28,'2.09.2021'!A$3:'2.09.2021'!I$202,5,) -> 44337 | F28: 44455 | G28: =VLOOKUP(A28,'2.09.2021'!A$3:'2.09.2021'!I$202,7,) -> 0.15902778 | H28: =VLOOKUP(A28,'2.09.2021'!A$3:'2.09.2021'!I$202,8,) -> POP | I28: =VLOOKUP(A28,'2.09.2021'!A$3:'2.09.2021'!I$202,9,) -> SUA | J28: =IF(ISNUMBER(SEARCH("with",A28)),"Da","Nu") -> Nu
A29: Cold Heart - PNAU Remix | B29: Elton John | C29: 14689417 | D29: =(C29/1000*5) -> 73447.085 | E29: =VLOOKUP(A29,'2.09.2021'!A$3:'2.09.2021'!I$202,5,) -> 44421 | F29: 44455 | G29: =VLOOKUP(A29,'2.09.2021'!A$3:'2.09.2021'!I$202,7,) -> 0.14027778 | H29: =VLOOKUP(A29,'2.09.2021'!A$3:'2.09.2021'!I$202,8,) -> POP | I29: =VLOOKUP(A29,'2.09.2021'!A$3:'2.09.2021'!I$202,9,) -> Marea Britanie | J29: =IF(ISNUMBER(SEARCH("with",A29)),"Da","Nu") -> Nu
A30: Peaches (with Daniel Caesar & Giveon) | B30: Justin Bieber | C30: 14439357 | D30: =(C30/1000*5) -> 72196.785 | E30: =VLOOKUP(A30,'2.09.2021'!A$3:'2.09.2021'!I$202,5,) -> 44274 | F30: 44455 | G30: =VLOOKUP(A30,'2.09.2021'!A$3:'2.09.2021'!I$202,7,) -> 0.1375 | H30: =VLOOKUP(A30,'2.09.2021'!A$3:'2.09.2021'!I$202,8,) -> POP | I30: =VLOOKUP(A30,'2.09.2021'!A$3:'2.09.2021'!I$202,9,) -> Canada | J30: =IF(ISNUMBER(SEARCH("with",A30)),"Da","Nu") -> Da
A31: Take My Breath | B31: The Weeknd | C31: 14287625 | D31: =(C31/1000*5) -> 71438.125 | E31: =VLOOKUP(A31,'2.09.2021'!A$3:'2.09.2021'!I$202,5,) -> 44414 | F31: 44455 | G31: =VLOOKUP(A31,'2.09.2021'!A$3:'2.09.2021'!I$202,7,) -> 0.15277778 | H31: =VLOOKUP(A31,'2.09.2021'!A$3:'2.09.2021'!I$202,8,) -> R&B/SOUL | I31: =VLOOKUP(A31,'2.09.2021'!A$3:'2.09.2021'!I$202,9,) -> Canada | J31: =IF(ISNUMBER(SEARCH("with",A31)),"Da","Nu") -> Nu
A32: family ties (with Kendrick Lamar) | B32: Baby Keem | C32: 14079036 | D32: =(C32/1000*5) -> 70395.18 | E32: =VLOOKUP(A32,'2.09.2021'!A$3:'2.09.2021'!I$202,5,) -> 44435 | F32: 44455 | G32: =VLOOKUP(A32,'2.09.2021'!A$3:'2.09.2021'!I$202,7,) -> 0.175 | H32: =VLOOKUP(A32,'2.09.2021'!A$3:'2.09.2021'!I$202,8,) -> HIP-HOP/RAP | I32: =VLOOKUP(A32,'2.09.2021'!A$3:'2.09.2021'!I$202,9,) -> SUA | J32: =IF(ISNUMBER(SEARCH("with",A32)),"Da","Nu") -> Da
A33: I WANNA BE YOUR SLAVE | B33: Måneskin | C33: 14073872 | D33: =(C33/1000*5) -> 70369.36 | E33: =VLOOKUP(A33,'2.09.2021'!A$3:'2.09.2021'!I$202,5,) -> 44274 | F33: 44455 | G33: =VLOOKUP(A33,'2.09.2021'!A$3:'2.09.2021'!I$202,7,) -> 0.12013889 | H33: =VLOOKUP(A33,'2.09.2021'!A$3:'2.09.2021'!I$202,8,) -> ROCK | I33: =VLOOKUP(A33,'2.09.2021'!A$3:'2.09.2021'!I$202,9,) -> Italia | J33: =IF(ISNUMBER(SEARCH("with",A33)),"Da","Nu") -> Nu
A34: Life Goes On | B34: Oliver Tree | C34: 13828796 | D34: =(C34/1000*5) -> 69143.98 | E34: =VLOOKUP(A34,'23.09.2021'!A$3:'23.09.2021'!I$202,5,) -> 44460 | F34: 44455 | G34: =VLOOKUP(A34,'23.09.2021'!A$3:'23.09.2021'!I$202,7,) -> 0.13958333 | H34: =VLOOKUP(A34,'23.09.2021'!A$3:'23.09.2021'!I$202,8,) -> POP | I34: =VLOOKUP(A34,'23.09.2021'!A$3:'23.09.2021'!I$202,9,) -> SUA | J34: =IF(ISNUMBER(SEARCH("with",A34)),"Da","Nu") -> Nu
A35: Champagne Poetry | B35: Drake | C35: 13239717 | D35: =(C35/1000*5) -> 66198.585 | E35: =VLOOKUP(A35,'23.09.2021'!A$3:'23.09.2021'!I$202,5,) -> 44460 | F35: 44455 | G35: =VLOOKUP(A35,'23.09.2021'!A$3:'23.09.2021'!I$202,7,) -> 0.16388889 | H35: =VLOOKUP(A35,'23.09.2021'!A$3:'23.09.2021'!I$202,8,) -> HIP-HOP/RAP | I35: =VLOOKUP(A35,'23.09.2021'!A$3:'23.09.2021'!I$202,9,) -> Canada | J35: =IF(ISNUMBER(SEARCH("with",A35)),"Da","Nu") -> Nu
A36: Blinding Lights | B36: The Weeknd | C36: 13064129 | D36: =(C36/1000*5) -> 65320.645 | E36: =VLOOKUP(A36,'2.09.2021'!A$3:'2.09.2021'!I$202,5,) -> 43798 | F36: 44455 | G36: =VLOOKUP(A36,'2.09.2021'!A$3:'2.09.2021'!I$202,7,) -> 0.13958333 | H36: =VLOOKUP(A36,'2.09.2021'!A$3:'2.09.2021'!I$202,8,) -> R&B/SOUL | I36: =VLOOKUP(A36,'2.09.2021'!A$3:'2.09.2021'!I$202,9,) -> Canada | J36: =IF(ISNUMBER(SEARCH("with",A36)),"Da","Nu") -> Nu
A37: Save Your Tears (with Ariana Grande) (Remix) | B37: The Weeknd | C37: 12574176 | D37: =(C37/1000*5) -> 62870.88 | E37: =VLOOKUP(A37,'2.09.2021'!A$3:'2.09.2021'!I$202,5,) -> 43910 | F37: 44455 | G37: =VLOOKUP(A37,'2.09.2021'!A$3:'2.09.2021'!I$202,7,) -> 0.14930556 | H37: =VLOOKUP(A37,'2.09.2021'!A$3:'2.09.2021'!I$202,8,) -> R&B/SOUL | I37: =VLOOKUP(A37,'2.09.2021'!A$3:'2.09.2021'!I$202,9,) -> Canada | J37: =IF(ISNUMBER(SEARCH("with",A37)),"Da","Nu") -> Da
A38: Get Into It (Yuh) | B38: Doja Cat | C38: 12006248 | D38: =(C38/1000*5) -> 60031.24 | E38: =VLOOKUP(A38,'2.09.2021'!A$3:'2.09.2021'!I$202,5,) -> 44372 | F38: 44455 | G38: =VLOOKUP(A38,'2.09.2021'!A$3:'2.09.2021'!I$202,7,) -> 0.095833333 | H38: =VLOOKUP(A38,'2.09.2021'!A$3:'2.09.2021'!I$202,8,) -> POP | I38: =VLOOKUP(A38,'2.09.2021'!A$3:'2.09.2021'!I$202,9,) -> SUA | J38: =IF(ISNUMBER(SEARCH("with",A38)),"Da","Nu") -> Nu
A39: PariÌs | B39: Ingratax | C39: 11940428 | D39: =(C39/1000*5) -> 59702.14 | E39: =VLOOKUP(A39,'23.09.2021'!A$3:'23.09.2021'!I$202,5,) -> 44460 | F39: 44455 | G39: =VLOOKUP(A39,'23.09.2021'!A$3:'23.09.2021'!I$202,7,) -> 0.13125 | H39: =VLOOKUP(A39,'23.09.2021'!A$3:'23.09.2021'!I$202,8,) -> ALTERNATIVE | I39: =VLOOKUP(A39,'23.09.2021'!A$3:'23.09.2021'!I$202,9,) -> Panama | J39: =IF(ISNUMBER(SEARCH("with",A39)),"Da","Nu") -> Nu
A40: 2055 | B40: Sleepy Hallow | C40: 11928780 | D40: =(C40/1000*5) -> 59643.9 | E40: =VLOOKUP(A40,'2.09.2021'!A$3:'2.09.2021'!I$202,5,) -> 44300 | F40: 44455 | G40: =VLOOKUP(A40,'2.09.2021'!A$3:'2.09.2021'!I$202,7,) -> 0.085416667 | H40: =VLOOKUP(A40,'2.09.2021'!A$3:'2.09.2021'!I$202,8,) -> HIP-HOP/RAP | I40: =VLOOKUP(A40,'2.09.2021'!A$3:'2.09.2021'!I$202,9,) -> Jamaica | J40: =IF(ISNUMBER(SEARCH("with",A40)),"Da","Nu") -> Nu
A41: drivers license | B41: Olivia Rodrigo | C41: 11772296 | D41: =(C41/1000*5) -> 58861.48 | E41: =VLOOKUP(A41,'2.09.2021'!A$3:'2.09.2021'!I$202,5,) -> 44204 | F41: 44455 | G41: =VLOOKUP(A41,'2.09.2021'!A$3:'2.09.2021'!I$202,7,) -> 0.16805556 | H41: =VLOOKUP(A41,'2.09.2021'!A$3:'2.09.2021'!I$202,8,) -> POP | I41: =VLOOKUP(A41,'2.09.2021'!A$3:'2.09.2021'!I$202,9,) -> SUA | J41: =IF(ISNUMBER(SEARCH("with",A41)),"Da","Nu") -> Nu
...

Sheet 23.09.2021
A1: Numele Melodiei | B1: Artist | C1: Numar vizualizari | D1: Venituri (nr vizulizari/1000*5) | E1: Data Lansarii | F1: Aparitii in top 200 | G1: Durata Melodiei | H1: Genul de Muzica | I1: Nationalitatea Artistului | J1: Colaborare
A3: STAY (with Justin Bieber) | B3: The Kid LAROI | C3: 65706259 | D3: =(C3/1000*5) -> 328531.3 | E3: =VLOOKUP(A3,'2.09.2021'!A$3:'2.09.2021'!I$202,5,) -> 44386 | F3: 44462 | G3: =VLOOKUP(A3,'2.09.2021'!A$3:'2.09.2021'!I$202,7,) -> 0.097916667 | H3: =VLOOKUP(A3,'2.09.2021'!A$3:'2.09.2021'!I$202,8,) -> POP | I3: =VLOOKUP(A3,'2.09.2021'!A$3:'2.09.2021'!I$202,9,) -> Australia | J3: =IF(ISNUMBER(SEARCH("with",A3)),"Da","Nu") -> Da
A4: Girls Want Girls (with Lil Baby) | B4: Drake | C4: 45594878 | D4: =(C4/1000*5) -> 227974.39 | E4: 44460 | F4: 44462 | G4: 0.085416667 | H4: hIP-HOP/RAP | I4: Canada | J4: =IF(ISNUMBER(SEARCH("with",A4)),"Da","Nu") -> Da
A5: Fair Trade (with Travis Scott) | B5: Drake | C5: 43845716 | D5: =(C5/1000*5) -> 219228.58 | E5: 44460 | F5: 44462 | G5: 0.14097222 | H5: hIP-HOP/RAP | I5: Canada | J5: =IF(ISNUMBER(SEARCH("with",A5)),"Da","Nu") -> Da
A6: INDUSTRY BABY (with Jack Harlow) | B6: Lil Nas X | C6: 42154185 | D6: =(C6/1000*5) -> 210770.92 | E6: =VLOOKUP(A6,'2.09.2021'!A$3:'2.09.2021'!I$202,5,) -> 44400 | F6: 44462 | G6: =VLOOKUP(A6,'2.09.2021'!A$3:'2.09.2021'!I$202,7,) -> 0.14722222 | H6: HIP-HOP/RAP | I6: =VLOOKUP(A6,'2.09.2021'!A$3:'2.09.2021'!I$202,9,) -> SUA | J6: =IF(ISNUMBER(SEARCH("with",A6)),"Da","Nu") -> Da
A7: Way 2 Sexy (with Future & Young Thug) | B7: Drake | C7: 38422223 | D7: =(C7/1000*5) -> 192111.11 | E7: 44460 | F7: 44462 | G7: 0.055555556 | H7: HIP-HOP/RAP | I7: Canada | J7: =IF(ISNUMBER(SEARCH("with",A7)),"Da","Nu") -> Da
A8: Champagne Poetry | B8: Drake | C8: 34053174 | D8: =(C8/1000*5) -> 170265.87 | E8: 44460 | F8: 44462 | G8: 0.16388889 | H8: HIP-HOP/RAP | I8: Canada | J8: =IF(ISNUMBER(SEARCH("with",A8)),"Da","Nu") -> Nu
A9: Bad Habits | B9: Ed Sheeran | C9: 32477559 | D9: =(C9/1000*5) -> 162387.8 | E9: =VLOOKUP(A9,'2.09.2021'!A$3:'2.09.2021'!I$202,5,) -> 44358 | F9: 44462 | G9: =VLOOKUP(A9,'2.09.2021'!A$3:'2.09.2021'!I$202,7,) -> 0.14722222 | H9: =VLOOKUP(A9,'2.09.2021'!A$3:'2.09.2021'!I$202,8,) -> POP | I9: =VLOOKUP(A9,'2.09.2021'!A$3:'2.09.2021'!I$202,9,) -> Marea Britanie | J9: =IF(ISNUMBER(SEARCH("with",A9)),"Da","Nu") -> Nu
A10: Beggin' | B10: Måneskin | C10: 29650985 | D10: =(C10/1000*5) -> 148254.92 | E10: =VLOOKUP(A10,'2.09.2021'!A$3:'2.09.2021'!I$202,5,) -> 43077 | F10: 44462 | G10: =VLOOKUP(A10,'2.09.2021'!A$3:'2.09.2021'!I$202,7,) -> 0.14652778 | H10: =VLOOKUP(A10,'2.09.2021'!A$3:'2.09.2021'!I$202,8,) -> ROCK | I10: =VLOOKUP(A10,'2.09.2021'!A$3:'2.09.2021'!I$202,9,) -> Italia | J10: =IF(ISNUMBER(SEARCH("with",A10)),"Da","Nu") -> Nu
A11: Pepas | B11: Farruko | C11: 29585088 | D11: =(C11/1000*5) -> 147925.44 | E11: =VLOOKUP(A11,'2.09.2021'!A$3:'2.09.2021'!I$202,5,) -> 44538 | F11: 44462 | G11: =VLOOKUP(A11,'2.09.2021'!A$3:'2.09.2021'!I$202,7,) -> 0.19930556 | H11: =VLOOKUP(A11,'2.09.2021'!A$3:'2.09.2021'!I$202,8,) -> LATIN URBAN | I11: =VLOOKUP(A11,'2.09.2021'!A$3:'2.09.2021'!I$202,9,) -> Puerto Rico | J11: =IF(ISNUMBER(SEARCH("with",A11)),"Da","Nu") -> Nu
A12: Knife Talk (with 21 Savage ft. Project Pat) | B12: Drake | C12: 28347807 | D12: =(C12/1000*5) -> 141739.04 | E12: 44460 | F12: 44462 | G12: 0.16736111 | H12: HIP-HOP/RAP | I12: Canada | J12: =IF(ISNUMBER(SEARCH("with",A12)),"Da","Nu") -> Da
A13: Woman | B13: Doja Cat | C13: 27507841 | D13: =(C13/1000*5) -> 137539.21 | E13: =VLOOKUP(A13,'2.09.2021'!A$3:'2.09.2021'!I$202,5,) -> 44374 | F13: 44462 | G13: =VLOOKUP(A13,'2.09.2021'!A$3:'2.09.2021'!I$202,7,) -> 0.10069444 | H13: =VLOOKUP(A13,'2.09.2021'!A$3:'2.09.2021'!I$202,8,) -> POP | I13: =VLOOKUP(A13,'2.09.2021'!A$3:'2.09.2021'!I$202,9,) -> SUA | J13: =IF(ISNUMBER(SEARCH("with",A13)),"Da","Nu") -> Nu
A14: Papiâ€™s Home | B14: Drake | C14: 27368851 | D14: =(C14/1000*5) -> 136844.26 | E14: 44460 | F14: 44462 | G14: 0.14305556 | H14: HIP-HOP/RAP | I14: Canada | J14: =IF(ISNUMBER(SEARCH("with",A14)),"Da","Nu") -> Nu
A15: Hurricane | B15: Kanye West | C15: 27212883 | D15: =(C15/1000*5) -> 136064.42 | E15: =VLOOKUP(A15,'2.09.2021'!A$3:'2.09.2021'!I$202,5,) -> 44416 | F15: 44462 | G15: =VLOOKUP(A15,'2.09.2021'!A$3:'2.09.2021'!I$202,7,) -> 0.16875 | H15: =VLOOKUP(A15,'2.09.2021'!A$3:'2.09.2021'!I$202,8,) -> HIP-HOP/RAP | I15: =VLOOKUP(A15,'2.09.2021'!A$3:'2.09.2021'!I$202,9,) -> SUA | J15: =IF(ISNUMBER(SEARCH("with",A15)),"Da","Nu") -> Nu
A16: good 4 u | B16: Olivia Rodrigo | C16: 26877818 | D16: =(C16/1000*5) -> 134389.09 | E16: =VLOOKUP(A16,'2.09.2021'!A$3:'2.09.2021'!I$202,5,) -> 44337 | F16: 44462 | G16: =VLOOKUP(A16,'2.09.2021'!A$3:'2.09.2021'!I$202,7,) -> 0.12361111 | H16: =VLOOKUP(A16,'2.09.2021'!A$3:'2.09.2021'!I$202,8,) -> POP | I16: =VLOOKUP(A16,'2.09.2021'!A$3:'2.09.2021'!I$202,9,) -> SUA | J16: =IF(ISNUMBER(SEARCH("with",A16)),"Da","Nu") -> Nu
A17: TSU | B17: Drake | C17: 26226066 | D17: =(C17/1000*5) -> 131130.33 | E17: 44460 | F17: 44462 | G17: 0.13958333 | H17: HIP-HOP/RAP | I17: Canada | J17: =IF(ISNUMBER(SEARCH("with",A17)),"Da","Nu") -> Nu
A18: In The Bible (with Lil Durk & Giveon) | B18: Drake | C18: 26043915 | D18: =(C18/1000*5) -> 130219.58 | E18: 44460 | F18: 44462 | G18: 0.099305556 | H18: HIP-HOP/RAP | I18: Canada | J18: =IF(ISNUMBER(SEARCH("with",A18)),"Da","Nu") -> Da
A19: Love All (with JAY-Z) | B19: Drake | C19: 25554209 | D19: =(C19/1000*5) -> 127771.04 | E19: 44460 | F19: 44462 | G19: 0.12777778 | H19: HIP-HOP/RAP | I19: Canada | J19: =IF(ISNUMBER(SEARCH("with",A19)),"Da","Nu") -> Da
A20: Need To Know | B20: Doja Cat | C20: 25440855 | D20: =(C20/1000*5) -> 127204.27 | E20: =VLOOKUP(A20,'2.09.2021'!A$3:'2.09.2021'!I$202,5,) -> 44371 | F20: 44462 | G20: =VLOOKUP(A20,'2.09.2021'!A$3:'2.09.2021'!I$202,7,) -> 0.14583333 | H20: =VLOOKUP(A20,'2.09.2021'!A$3:'2.09.2021'!I$202,8,) -> POP | I20: =VLOOKUP(A20,'2.09.2021'!A$3:'2.09.2021'!I$202,9,) -> SUA | J20: =IF(ISNUMBER(SEARCH("with",A20)),"Da","Nu") -> Nu
A21: Heat Waves | B21: Glass Animals | C21: 24827159 | D21: =(C21/1000*5) -> 124135.79 | E21: =VLOOKUP(A21,'2.09.2021'!A$3:'2.09.2021'!I$202,5,) -> 44050 | F21: 44462 | G21: =VLOOKUP(A21,'2.09.2021'!A$3:'2.09.2021'!I$202,7,) -> 0.16527778 | H21: =VLOOKUP(A21,'2.09.2021'!A$3:'2.09.2021'!I$202,8,) -> POP | I21: =VLOOKUP(A21,'2.09.2021'!A$3:'2.09.2021'!I$202,9,) -> Marea Britanie | J21: =IF(ISNUMBER(SEARCH("with",A21)),"Da","Nu") -> Nu
A22: No Friends In The Industry | B22: Drake | C22: 23993346 | D22: =(C22/1000*5) -> 119966.73 | E22: 44460 | F22: 44462 | G22: 0.12847222 | H22: HIP-HOP/RAP | I22: Canada | J22: =IF(ISNUMBER(SEARCH("with",A22)),"Da","Nu") -> Nu
A23: Happier Than Ever | B23: Billie Eilish | C23: 22684148 | D23: =(C23/1000*5) -> 113420.74 | E23: =VLOOKUP(A23,'2.09.2021'!A$3:'2.09.2021'!I$202,5,) -> 44407 | F23: 44462 | G23: =VLOOKUP(A23,'2.09.2021'!A$3:'2.09.2021'!I$202,7,) -> 0.20694444 | H23: =VLOOKUP(A23,'2.09.2021'!A$3:'2.09.2021'!I$202,8,) -> ALTERNATIVE | I23: =VLOOKUP(A23,'2.09.2021'!A$3:'2.09.2021'!I$202,9,) -> SUA | J23: =IF(ISNUMBER(SEARCH("with",A23)),"Da","Nu") -> Nu
A24: N 2 Deep | B24: Drake | C24: 22025962 | D24: =(C24/1000*5) -> 110129.81 | E24: 44460 | F24: 44462 | G24: 0.15763889 | H24: HIP-HOP/RAP | I24: Canada | J24: =IF(ISNUMBER(SEARCH("with",A24)),"Da","Nu") -> Nu
A25: MONTERO (Call Me By Your Name) | B25: Lil Nas X | C25: 21529938 | D25: =(C25/1000*5) -> 107649.69 | E25: =VLOOKUP(A25,'2.09.2021'!A$3:'2.09.2021'!I$202,5,) -> 44456 | F25: 44462 | G25: =VLOOKUP(A25,'2.09.2021'!A$3:'2.09.2021'!I$202,7,) -> 0.095138889 | H25: =VLOOKUP(A25,'2.09.2021'!A$3:'2.09.2021'!I$202,8,) -> POP | I25: =VLOOKUP(A25,'2.09.2021'!A$3:'2.09.2021'!I$202,9,) -> SUA | J25: =IF(ISNUMBER(SEARCH("with",A25)),"Da","Nu") -> Nu
A26: Kiss Me More (with SZA) | B26: Doja Cat | C26: 20896669 | D26: =(C26/1000*5) -> 104483.35 | E26: =VLOOKUP(A26,'2.09.2021'!A$3:'2.09.2021'!I$202,5,) -> 44295 | F26: 44462 | G26: =VLOOKUP(A26,'2.09.2021'!A$3:'2.09.2021'!I$202,7,) -> 0.14444444 | H26: =VLOOKUP(A26,'2.09.2021'!A$3:'2.09.2021'!I$202,8,) -> POP | I26: =VLOOKUP(A26,'2.09.2021'!A$3:'2.09.2021'!I$202,9,) -> SUA | J26: =IF(ISNUMBER(SEARCH("with",A26)),"Da","Nu") -> Da
A27: Todo De Ti | B27: Rauw Alejandro | C27: 19097158 | D27: =(C27/1000*5) -> 95485.79 | E27: =VLOOKUP(A27,'2.09.2021'!A$3:'2.09.2021'!I$202,5,) -> 44338 | F27: 44462 | G27: =VLOOKUP(A27,'2.09.2021'!A$3:'2.09.2021'!I$202,7,) -> 0.13819444 | H27: =VLOOKUP(A27,'2.09.2021'!A$3:'2.09.2021'!I$202,8,) -> LATIN URBAN | I27: =VLOOKUP(A27,'2.09.2021'!A$3:'2.09.2021'!I$202,9,) -> Puerto Rico | J27: =IF(ISNUMBER(SEARCH("with",A27)),"Da","Nu") -> Nu
A28: Pipe Down | B28: Drake | C28: 18888249 | D28: =(C28/1000*5) -> 94441.245 | E28: 44460 | F28: 44462 | G28: 0.15625 | H28: HIP-HOP/RAP | I28: Canada | J28: =IF(ISNUMBER(SEARCH("with",A28)),"Da","Nu") -> Nu
A29: 7am On Bridle Path | B29: Drake | C29: 18180843 | D29: =(C29/1000*5) -> 90904.215 | E29: 44460 | F29: 44462 | G29: 0.10486111 | H29: HIP-HOP/RAP | I29: Canada | J29: =IF(ISNUMBER(SEARCH("with",A29)),"Da","Nu") -> Nu
A30: Volví | B30: Aventura | C30: 17626028 | D30: =(C30/1000*5) -> 88130.14 | E30: =VLOOKUP(A30,'2.09.2021'!A$3:'2.09.2021'!I$202,5,) -> 44411 | F30: 44462 | G30: =VLOOKUP(A30,'2.09.2021'!A$3:'2.09.2021'!I$202,7,) -> 0.15972222 | H30: =VLOOKUP(A30,'2.09.2021'!A$3:'2.09.2021'!I$202,8,) -> LATIN URBAN | I30: =VLOOKUP(A30,'2.09.2021'!A$3:'2.09.2021'!I$202,9,) -> Republica Dominicană | J30: =IF(ISNUMBER(SEARCH("with",A30)),"Da","Nu") -> Nu
A31: Yonaguni | B31: Bad Bunny | C31: 17385575 | D31: =(C31/1000*5) -> 86927.875 | E31: =VLOOKUP(A31,'2.09.2021'!A$3:'2.09.2021'!I$202,5,) -> 44351 | F31: 44462 | G31: =VLOOKUP(A31,'2.09.2021'!A$3:'2.09.2021'!I$202,7,) -> 0.14305556 | H31: =VLOOKUP(A31,'2.09.2021'!A$3:'2.09.2021'!I$202,8,) -> LATIN URBAN | I31: =VLOOKUP(A31,'2.09.2021'!A$3:'2.09.2021'!I$202,9,) -> Puerto Rico | J31: =IF(ISNUMBER(SEARCH("with",A31)),"Da","Nu") -> Nu
A32: Race My Mind | B32: Drake | C32: 17035250 | D32: =(C32/1000*5) -> 85176.25 | E32: 44460 | F32: 44462 | G32: 0.088888889 | H32: HIP-HOP/RAP | I32: Canada | J32: =IF(ISNUMBER(SEARCH("with",A32)),"Da","Nu") -> Nu
A33: IMY2 (with Kid Cudi) | B33: Drake | C33: 16808455 | D33: =(C33/1000*5) -> 84042.275 | E33: 44460 | F33: 44462 | G33: 0.13333333 | H33: HIP-HOP/RAP | I33: Canada | J33: =IF(ISNUMBER(SEARCH("with",A33)),"Da","Nu") -> Da
A34: Off The Grid | B34: Kanye West | C34: 16413179 | D34: =(C34/1000*5) -> 82065.895 | E34: =VLOOKUP(A34,'2.09.2021'!A$3:'2.09.2021'!I$202,5,) -> 44437 | F34: 44462 | G34: =VLOOKUP(A34,'2.09.2021'!A$3:'2.09.2021'!I$202,7,) -> 0.23541667 | H34: =VLOOKUP(A34,'2.09.2021'!A$3:'2.09.2021'!I$202,8,) -> HIP-HOP/RAP | I34: =VLOOKUP(A34,'2.09.2021'!A$3:'2.09.2021'!I$202,9,) -> SUA | J34: =IF(ISNUMBER(SEARCH("with",A34)),"Da","Nu") -> Nu
A35: I WANNA BE YOUR SLAVE | B35: Måneskin | C35: 16188501 | D35: =(C35/1000*5) -> 80942.505 | E35: =VLOOKUP(A35,'2.09.2021'!A$3:'2.09.2021'!I$202,5,) -> 44274 | F35: 44462 | G35: =VLOOKUP(A35,'2.09.2021'!A$3:'2.09.2021'!I$202,7,) -> 0.12013889 | H35: =VLOOKUP(A35,'2.09.2021'!A$3:'2.09.2021'!I$202,8,) -> ROCK | I35: =VLOOKUP(A35,'2.09.2021'!A$3:'2.09.2021'!I$202,9,) -> Italia | J35: =IF(ISNUMBER(SEARCH("with",A35)),"Da","Nu") -> Nu
A36: Fountains (with Tems) | B36: Drake | C36: 16082820 | D36: =(C36/1000*5) -> 80414.1 | E36: 44460 | F36: 44462 | G36: 0.089583333 | H36: HIP-HOP/RAP | I36: Canada | J36: =IF(ISNUMBER(SEARCH("with",A36)),"Da","Nu") -> Da
A37: Levitating (with DaBaby) | B37: Dua Lipa | C37: 16076912 | D37: =(C37/1000*5) -> 80384.56 | E37: =VLOOKUP(A37,'2.09.2021'!A$3:'2.09.2021'!I$202,5,) -> 43917 | F37: 44462 | G37: =VLOOKUP(A37,'2.09.2021'!A$3:'2.09.2021'!I$202,7,) -> 0.14097222 | H37: =VLOOKUP(A37,'2.09.2021'!A$3:'2.09.2021'!I$202,8,) -> POP | I37: =VLOOKUP(A37,'2.09.2021'!A$3:'2.09.2021'!I$202,9,) -> Marea Britanie | J37: =IF(ISNUMBER(SEARCH("with",A37)),"Da","Nu") -> Da
A38: Take My Breath | B38: The Weeknd | C38: 15826162 | D38: =(C38/1000*5) -> 79130.81 | E38: =VLOOKUP(A38,'2.09.2021'!A$3:'2.09.2021'!I$202,5,) -> 44414 | F38: 44462 | G38: =VLOOKUP(A38,'2.09.2021'!A$3:'2.09.2021'!I$202,7,) -> 0.15277778 | H38: =VLOOKUP(A38,'2.09.2021'!A$3:'2.09.2021'!I$202,8,) -> R&B/SOUL | I38: =VLOOKUP(A38,'2.09.2021'!A$3:'2.09.2021'!I$202,9,) -> Canada | J38: =IF(ISNUMBER(SEARCH("with",A38)),"Da","Nu") -> Nu
A39: Yebbaâ€™s Heartbreak | B39: Drake | C39: 15567041 | D39: =(C39/1000*5) -> 77835.205 | E39: 44460 | F39: 44462 | G39: 0.13888889 | H39: HIP-HOP/RAP | I39: Canada | J39: =IF(ISNUMBER(SEARCH("with",A39)),"Da","Nu") -> Nu
A40: Qué Más Pues? | B40: J Balvin | C40: 15558142 | D40: =(C40/1000*5) -> 77790.71 | E40: =VLOOKUP(A40,'2.09.2021'!A$3:'2.09.2021'!I$202,5,) -> 44344 | F40: 44462 | G40: =VLOOKUP(A40,'2.09.2021'!A$3:'2.09.2021'!I$202,7,) -> 0.15069444 | H40: =VLOOKUP(A40,'2.09.2021'!A$3:'2.09.2021'!I$202,8,) -> LATIN URBAN | I40: =VLOOKUP(A40,'2.09.2021'!A$3:'2.09.2021'!I$202,9,) -> Columbia | J40: =IF(ISNUMBER(SEARCH("with",A40)),"Da","Nu") -> Nu
A41: traitor | B41: Olivia Rodrigo | C41: 15470078 | D41: =(C41/1000*5) -> 77350.39 | E41: =VLOOKUP(A41,'2.09.2021'!A$3:'2.09.2021'!I$202,5,) -> 44337 | F41: 44462 | G41: =VLOOKUP(A41,'2.09.2021'!A$3:'2.09.2021'!I$202,7,) -> 0.15902778 | H41: =VLOOKUP(A41,'2.09.2021'!A$3:'2.09.2021'!I$202,8,) -> POP | I41: =VLOOKUP(A41,'2.09.2021'!A$3:'2.09.2021'!I$202,9,) -> SUA | J41: =IF(ISNUMBER(SEARCH("with",A41)),"Da","Nu") -> Nu
...

Sheet 30.09.2021
A1: Numele Melodiei | B1: Artist | C1: Numar vizualizari | D1: Venituri (nr vizulizari/1000*5) | E1: Data Lansarii | F1: Aparitii in top 200 | G1: Durata Melodiei | H1: Genul de Muzica | I1: Nationalitatea Artistului | J1: Colaborare
A3: STAY (with Justin Bieber) | B3: The Kid LAROI | C3: 55885730 | D3: =(C3/1000*5) -> 279428.65 | E3: =VLOOKUP(A3,'2.09.2021'!A$3:'2.09.2021'!I$202,5,) -> 44386 | F3: 44469 | G3: =VLOOKUP(A3,'2.09.2021'!A$3:'2.09.2021'!I$202,7,) -> 0.097916667 | H3: =VLOOKUP(A3,'2.09.2021'!A$3:'2.09.2021'!I$202,8,) -> POP | I3: =VLOOKUP(A3,'2.09.2021'!A$3:'2.09.2021'!I$202,9,) -> Australia | J3: =IF(ISNUMBER(SEARCH("with",A3)),"Da","Nu") -> Da
A4: INDUSTRY BABY (with Jack Harlow) | B4: Lil Nas X | C4: 47510601 | D4: =(C4/1000*5) -> 237553.01 | E4: =VLOOKUP(A4,'2.09.2021'!A$3:'2.09.2021'!I$202,5,) -> 44400 | F4: 44469 | G4: =VLOOKUP(A4,'2.09.2021'!A$3:'2.09.2021'!I$202,7,) -> 0.14722222 | H4: =VLOOKUP(A4,'2.09.2021'!A$3:'2.09.2021'!I$202,8,) -> HIP-HOP/RAP | I4: =VLOOKUP(A4,'2.09.2021'!A$3:'2.09.2021'!I$202,9,) -> SUA | J4: =IF(ISNUMBER(SEARCH("with",A4)),"Da","Nu") -> Da
A5: My Universe | B5: Coldplay | C5: 32790116 | D5: =(C5/1000*5) -> 163950.58 | E5: 44339 | F5: 44469 | G5: 0.14097222 | H5: ROCK | I5: Marea Britanie | J5: =IF(ISNUMBER(SEARCH("with",A5)),"Da","Nu") -> Nu
A6: Heat Waves | B6: Glass Animals | C6: 31067813 | D6: =(C6/1000*5) -> 155339.07 | E6: =VLOOKUP(A6,'2.09.2021'!A$3:'2.09.2021'!I$202,5,) -> 44050 | F6: 44469 | G6: =VLOOKUP(A6,'2.09.2021'!A$3:'2.09.2021'!I$202,7,) -> 0.16527778 | H6: =VLOOKUP(A6,'2.09.2021'!A$3:'2.09.2021'!I$202,8,) -> POP | I6: =VLOOKUP(A6,'2.09.2021'!A$3:'2.09.2021'!I$202,9,) -> Marea Britanie | J6: =IF(ISNUMBER(SEARCH("with",A6)),"Da","Nu") -> Nu
A7: Pepas | B7: Farruko | C7: 29289287 | D7: =(C7/1000*5) -> 146446.43 | E7: =VLOOKUP(A7,'2.09.2021'!A$3:'2.09.2021'!I$202,5,) -> 44538 | F7: 44469 | G7: =VLOOKUP(A7,'2.09.2021'!A$3:'2.09.2021'!I$202,7,) -> 0.19930556 | H7: =VLOOKUP(A7,'2.09.2021'!A$3:'2.09.2021'!I$202,8,) -> LATIN URBAN | I7: =VLOOKUP(A7,'2.09.2021'!A$3:'2.09.2021'!I$202,9,) -> Puerto Rico | J7: =IF(ISNUMBER(SEARCH("with",A7)),"Da","Nu") -> Nu
A8: Bad Habits | B8: Ed Sheeran | C8: 29024050 | D8: =(C8/1000*5) -> 145120.25 | E8: =VLOOKUP(A8,'2.09.2021'!A$3:'2.09.2021'!I$202,5,) -> 44358 | F8: 44469 | G8: =VLOOKUP(A8,'2.09.2021'!A$3:'2.09.2021'!I$202,7,) -> 0.14722222 | H8: =VLOOKUP(A8,'2.09.2021'!A$3:'2.09.2021'!I$202,8,) -> POP | I8: =VLOOKUP(A8,'2.09.2021'!A$3:'2.09.2021'!I$202,9,) -> Marea Britanie | J8: =IF(ISNUMBER(SEARCH("with",A8)),"Da","Nu") -> Nu
A9: Woman | B9: Doja Cat | C9: 27995514 | D9: =(C9/1000*5) -> 139977.57 | E9: =VLOOKUP(A9,'2.09.2021'!A$3:'2.09.2021'!I$202,5,) -> 44374 | F9: 44469 | G9: =VLOOKUP(A9,'2.09.2021'!A$3:'2.09.2021'!I$202,7,) -> 0.10069444 | H9: =VLOOKUP(A9,'2.09.2021'!A$3:'2.09.2021'!I$202,8,) -> POP | I9: =VLOOKUP(A9,'2.09.2021'!A$3:'2.09.2021'!I$202,9,) -> SUA | J9: =IF(ISNUMBER(SEARCH("with",A9)),"Da","Nu") -> Nu
